<?xml version="1.0" ?>
<robot name="spot" xmlns:xacro="http://www.ros.org/wiki/xacro">
    <xacro:arg name="dir_" default="file:///home/jing/Documents/spot/src/test/pyt/models/spot"/>

    <material name="Black">
        <color rgba="0.1 0.1 0.1 1.0"/>
    </material>
    <material name="Blue">
    <color rgba="0.0 0.0 0.8 1.0"/>
    </material>
    <material name="Green">
    <color rgba="0.0 0.8 0.0 1.0"/>
    </material>
    <material name="Grey">
    <color rgba="0.7 0.7 0.7 1.0"/>
    </material>
    <material name="DarkGrey">
    <color rgba="0.3 0.3 0.3 1.0"/>
    </material>
    <material name="Red">
    <color rgba="0.8 0.0 0.0 1.0"/>
    </material>
    <material name="White">
    <color rgba="1.0 1.0 1.0 1.0"/>
    </material>
    <material name="Yellow">
    <color rgba="0.8 0.8 0.0 1.0"/>
    </material>

    <link name="body">
        <visual>
            <origin rpy="3.14159265359 0 0" xyz="0 0 0"/>
            <geometry>
                <mesh filename="package://legged/models/wheeledspot/meshes/body.dae" />
            </geometry>
        </visual>
        <collision>
            <geometry>
                <box size="0.892 0.256 0.214"/>
            </geometry>
        </collision>
        <inertial>
             <mass value="16.25" />
             <inertia  ixx="0.085" ixy="0.0"  ixz="0.0"  iyy="1.045"  iyz="0.0"  izz="1.042" />
      </inertial>
    </link>

    <link name="base_link"/>
    <joint name="base_link_joint" type="fixed">
        <origin xyz="0 0 0" rpy="0 0 0" />
        <parent link="base_link" />
        <child link="body" />
    </joint>

    <link name="front_rail"/>
    <joint name="front_rail_joint" type="fixed">
        <origin xyz="0.223 0 0.0805" rpy="0 0 0" />
        <parent link="body" />
        <child link="front_rail" />
    </joint>

    <link name="rear_rail"/>
    <joint name="rear_rail_joint" type="fixed">
        <origin xyz="-0.223 0 0.0805" rpy="0 0 0" />
        <parent link="body" />
        <child link="rear_rail" />
    </joint> 

    <link name="front_left_hip">
        <visual>
            <origin rpy="3.14159265359 0 0" xyz="0 0 0"/>
            <geometry>
                <mesh filename="package://legged/models/wheeledspot/meshes/front_left_hip.dae" />
            </geometry>
        </visual>
        <collision>
            <origin xyz="-0.02 0.015 0" rpy="0 1.5707963268 0"/>
            <geometry>
                <cylinder length="0.15" radius="0.05"/> 
            </geometry>
        </collision>
        <inertial>
            <mass value="1.5" />
          <inertia  ixx="0.0605" ixy="0.0"  ixz="0.0"  iyy="0.0"  iyz="0.0"  izz="0.0" />
      </inertial>
    </link>
    
    <joint name="front_left_hip_x" type="fixed">
        <origin xyz="0.29785 0.05500 0.00000" rpy="0 0 0" />
        <axis xyz="1 0 0" />
        <parent link="body" />
        <child link="front_left_hip" />
    </joint>

    <link name="front_left_upper_leg">
        <visual>
            <origin rpy="3.14159265359 -1.5707963268 0" xyz="0 0 0"/>
            <geometry>
                <mesh filename="package://legged/models/wheeledspot/meshes/front_left_upper_leg.dae" />
            </geometry>
        </visual>
        <collision>
            <origin xyz="0.0 0.01 -0.14" rpy="0 0 0"/>
            <geometry>
                <box size="0.1 0.1 0.41"/>
            </geometry>
        </collision>
        <inertial>
          <mass value="1.5" />
          <inertia  ixx="0.0" ixy="0.0"  ixz="0.0"  iyy="0.05"  iyz="0.0"  izz="0.0" />
      </inertial>
    </link>
    
    <joint name="front_left_hip_y" type="fixed">
        <origin xyz="0.0 0.110945 0.0" rpy="0 0 0" />
        <axis xyz="0 1 0" />
        <parent link="front_left_hip" />
        <child link="front_left_upper_leg" />
    </joint>

    <!-- <link name="front_left_lower_leg">
      <visual>
        <origin rpy="3.14159265359 1.32 0" xyz="0 0 0"/>
          <geometry>
              <mesh filename="package://legged/models/wheeledspot/meshes/front_left_lower_leg.dae" />
          </geometry>
      </visual>
      <collision name="front_left_lower_leg_fixed_joint_lump__front_bump_sensor">
        <origin xyz="0.0 0.00 -0.16" rpy="0 0 0"/>
          <geometry>
              <box size="0.06 0.045 0.42"/>
          </geometry>
      </collision>
      <inertial>
          <mass value="1.0" />
          <inertia  ixx="0.0" ixy="0.0"  ixz="0.0"  iyy="0.045"  iyz="0.0"  izz="0.0" />
      </inertial>
    </link>

    <joint name="front_left_knee" type="fixed">
        <origin xyz="0.025 0.000 -0.3205" rpy="0 0 0" />
        <axis xyz="0 1 0" />
        <parent link="front_left_upper_leg" />
        <child link="front_left_lower_leg" />
    </joint> -->
    <link name="front_left_wheel_link">
        <contact>
          <lateral_friction value="1.0"/>
          <rolling_friction value="0.0"/>
          <stiffness value="30000"/>
          <damping value="1000"/>
        </contact>

        <inertial>
          <mass value="2.637"/>
          <origin xyz="0 0 0"/>
          <inertia ixx="0.02467" ixy="0" ixz="0" iyy="0.02467" iyz="0" izz="0.04411"/>
        </inertial>
        <visual>
          <origin rpy="0 0 0" xyz="0 0 0"/>
          <geometry>
            <mesh filename="package://legged/models/wheeledspot/meshes/wheel.dae"/>
          </geometry>
          <material name="DarkGrey"/>
        </visual>
        <collision>
          <origin rpy="1.570795 0 0" xyz="0 0 0"/>
          <geometry>
            <cylinder length="0.1143" radius="0.17775"/>
          </geometry>
        </collision>
    </link>
    <!-- <gazebo reference="front_left_wheel_link">
    <mu1 value="1.0"/>
    <mu2 value="1.0"/>
    <kp value="10000000.0"/>
    <kd value="1.0"/>
    <fdir1 value="1 0 0"/>
    <material>Gazebo/Grey</material>
    <turnGravityOff>false</turnGravityOff>
    </gazebo> -->
    <joint name="front_left_wheel" type="continuous">
        <origin xyz="-0.025 0.000 -0.4205" rpy="0 0 0" />
        <axis xyz="0 1 0" />
        <parent link="front_left_upper_leg" />
        <child link="front_left_wheel_link" />
    </joint>
    <transmission name="front_left_wheel_trans" type="SimpleTransmission">
        <type>transmission_interface/SimpleTransmission</type>
        <actuator name="front_left_wheel_motor">
          <mechanicalReduction>1</mechanicalReduction>
        </actuator>
        <joint name="front_left_wheel">
          <hardwareInterface>VelocityJointInterface</hardwareInterface>
        </joint>
    </transmission>





    <link name="front_right_hip">
      <visual>
        <origin rpy="3.14159265359 0 0" xyz="0 0 0"/>
          <geometry>
              <mesh filename="package://legged/models/wheeledspot/meshes/front_right_hip.dae" />
          </geometry>
      </visual>
      <collision>
        <origin xyz="-0.02 -0.015 0" rpy="0 1.5707963268 0"/>
          <geometry>
              <cylinder length="0.15" radius="0.05"/> 
          </geometry>
      </collision>
      <inertial>
        <mass value="1.5" />
        <inertia  ixx="0.0605" ixy="0.0"  ixz="0.0"  iyy="0.0"  iyz="0.0"  izz="0.0" />
      </inertial>
    </link>

    <joint name="front_right_hip_x" type="fixed">
        <origin xyz="0.29785 -0.05500 0.00000" rpy="0 0 0" />
        <axis xyz="1 0 0" />
        <parent link="body" />
        <child link="front_right_hip" />
    </joint>

    <link name="front_right_upper_leg">
      <visual>
        <origin rpy="3.14159265359 -1.5707963268 0" xyz="0 0 0"/>
          <geometry>
              <mesh filename="package://legged/models/wheeledspot/meshes/front_right_upper_leg.dae" />
          </geometry>
      </visual>
      <collision>
        <origin xyz="0.0 -0.01 -0.14" rpy="0 0 0"/>
          <geometry>
              <box size="0.1 0.1 0.41"/>
          </geometry>
      </collision>
      <inertial>
        <mass value="1.5" />
        <inertia  ixx="0.0" ixy="0.0"  ixz="0.0"  iyy="0.05"  iyz="0.0"  izz="0.0" />
      </inertial>
    </link>

    <joint name="front_right_hip_y" type="fixed">
        <origin xyz="0.0 -0.110945 0.0" rpy="0 0 0" />
        <axis xyz="0 1 0" />
        <parent link="front_right_hip" />
        <child link="front_right_upper_leg" />
    </joint>

    <!-- <link name="front_right_lower_leg">
        <visual>
            <origin rpy="3.14159265359 1.32 0" xyz="0 0 0"/>
            <geometry>
                <mesh filename="package://legged/models/wheeledspot/meshes/front_right_lower_leg.dae" />
            </geometry>
        </visual>
        <collision name="front_right_lower_leg_fixed_joint_lump__front_bump_sensor">
            <origin xyz="0.0 0.00 -0.16" rpy="0 0 0"/>
            <geometry>
                <box size="0.06 0.045 0.42"/>
            </geometry>
        </collision>
        <inertial>
            <mass value="1.0" />
            <inertia  ixx="0.0" ixy="0.0"  ixz="0.0"  iyy="0.045"  iyz="0.0"  izz="0.0" />
        </inertial>
    </link>

    <joint name="front_right_knee" type="fixed">
        <origin xyz="0.025 0.000 -0.3205" rpy="0 0 0" />
        <axis xyz="0 1 0" />
        <parent link="front_right_upper_leg" />
        <child link="front_right_lower_leg" />
    </joint> -->

    <link name="front_right_wheel_link">
        <contact>
          <lateral_friction value="1.0"/>
          <rolling_friction value="0.0"/>
          <stiffness value="30000"/>
          <damping value="1000"/>
        </contact>

        <inertial>
          <mass value="2.637"/>
          <origin xyz="0 0 0"/>
          <inertia ixx="0.02467" ixy="0" ixz="0" iyy="0.02467" iyz="0" izz="0.04411"/>
        </inertial>
        <visual>
          <origin rpy="0 0 0" xyz="0 0 0"/>
          <geometry>
            <mesh filename="package://legged/models/wheeledspot/meshes/wheel.dae"/>
          </geometry>
          <material name="DarkGrey"/>
        </visual>
        <collision>
          <origin rpy="1.570795 0 0" xyz="0 0 0"/>
          <geometry>
            <cylinder length="0.1143" radius="0.17775"/>
          </geometry>
        </collision>
    </link>
  <!-- <gazebo reference="front_right_wheel_link">
    <mu1 value="1.0"/>
    <mu2 value="1.0"/>
    <kp value="10000000.0"/>
    <kd value="1.0"/>
    <fdir1 value="1 0 0"/>
    <material>Gazebo/Grey</material>
    <turnGravityOff>false</turnGravityOff>
  </gazebo> -->
    <joint name="front_right_wheel" type="continuous">
        <parent link="front_right_upper_leg"/>
        <child link="front_right_wheel_link"/>
        <origin xyz="-0.025 0.000 -0.4205" rpy="0 0 0" />
        <axis xyz="0 1 0" />
    </joint>
    <transmission name="front_right_wheel_trans" type="SimpleTransmission">
        <type>transmission_interface/SimpleTransmission</type>
        <actuator name="front_right_wheel_motor">
          <mechanicalReduction>1</mechanicalReduction>
        </actuator>
        <joint name="front_right_wheel">
          <hardwareInterface>VelocityJointInterface</hardwareInterface>
        </joint>
    </transmission>





   <link name="rear_left_hip">
        <visual>
            <origin rpy="3.14159265359 0 0" xyz="0 0 0"/>
            <geometry>
                <mesh filename="package://legged/models/wheeledspot/meshes/rear_left_hip.dae" />
            </geometry>
        </visual>
        <collision>
            <origin xyz="0.02 0.015 0" rpy="0 1.5707963268 0"/>
            <geometry>
                <cylinder length="0.15" radius="0.05"/> 
            </geometry>
        </collision>
        <inertial>
            <mass value="1.5" />
          <inertia  ixx="0.0605" ixy="0.0"  ixz="0.0"  iyy="0.0"  iyz="0.0"  izz="0.0" />
      </inertial>
    </link>

    <joint name="rear_left_hip_x" type="fixed">
        <origin xyz="-0.29785 0.05500 0.00000" rpy="0 0 0" />
        <axis xyz="1 0 0" />
        <parent link="body" />
        <child link="rear_left_hip" />
    </joint>

    <link name="rear_left_upper_leg">
        <visual>
            <origin rpy="3.14159265359 -1.39 0" xyz="0 0 0"/>
            <geometry>
                <mesh filename="package://legged/models/wheeledspot/meshes/rear_left_upper_leg.dae" />
            </geometry>
        </visual>
        <collision>
            <origin xyz="0.0 0.01 -0.14" rpy="0 0 0"/>
            <geometry>
                <box size="0.1 0.1 0.41"/>
            </geometry>
        </collision>
        <inertial>
           <mass value="1.5" />
           <inertia  ixx="0.0" ixy="0.0"  ixz="0.0"  iyy="0.05"  iyz="0.0"  izz="0.0" />
        </inertial>
    </link>

    <joint name="rear_left_hip_y" type="fixed">
        <origin xyz="0.0 0.110945 0.0" rpy="0 0 0" />
        <axis xyz="0 1 0" />
        <parent link="rear_left_hip" />
        <child link="rear_left_upper_leg" />
    </joint>

    <!-- <link name="rear_left_lower_leg">
        <visual>
            <origin rpy="3.14159265359 1.48 0" xyz="0 0 0"/>
            <geometry>
                <mesh filename="package://legged/models/wheeledspot/meshes/rear_left_lower_leg.dae" />
            </geometry>
        </visual>
        <collision name="rear_left_lower_leg_fixed_joint_lump__rear_bump_sensor">
            <origin xyz="0.0 0.00 -0.16" rpy="0 0 0"/>
            <geometry>
                <box size="0.06 0.045 0.42"/>
            </geometry>
        </collision>
        <inertial>
            <mass value="1.0" />
          <inertia  ixx="0.0" ixy="0.0"  ixz="0.0"  iyy="0.045"  iyz="0.0"  izz="0.0" />
      </inertial>
    </link> -->

    <!-- <joint name="rear_left_knee" type="fixed">
        <origin xyz="0.025 0.000 -0.3205" rpy="0 0 0" />
        <axis xyz="0 1 0" />
        <parent link="rear_left_upper_leg" />
        <child link="rear_left_lower_leg" />
    </joint> -->
    <link name="rear_left_wheel_link">
        <contact>
          <lateral_friction value="1.0"/>
          <rolling_friction value="0.0"/>
          <stiffness value="30000"/>
          <damping value="1000"/>
        </contact>

        <inertial>
          <mass value="2.637"/>
          <origin xyz="0 0 0"/>
          <inertia ixx="0.02467" ixy="0" ixz="0" iyy="0.02467" iyz="0" izz="0.04411"/>
        </inertial>
        <visual>
          <origin rpy="0 0 0" xyz="0 0 0"/>
          <geometry>
            <mesh filename="package://legged/models/wheeledspot/meshes/wheel.dae"/>
          </geometry>
          <material name="DarkGrey"/>
        </visual>
        <collision>
          <origin rpy="1.570795 0 0" xyz="0 0 0"/>
          <geometry>
            <cylinder length="0.1143" radius="0.17775"/>
          </geometry>
        </collision>
    </link>
    <!-- <gazebo reference="rear_left_wheel_link">
    <mu1 value="1.0"/>
    <mu2 value="1.0"/>
    <kp value="10000000.0"/>
    <kd value="1.0"/>
    <fdir1 value="1 0 0"/>
    <material>Gazebo/Grey</material>
    <turnGravityOff>false</turnGravityOff>
    </gazebo> -->
    <joint name="rear_left_wheel" type="continuous">
        <parent link="rear_left_upper_leg"/>
        <child link="rear_left_wheel_link"/>
        <origin xyz="0.025 0.000 -0.4205" rpy="0 0 0" />
        <axis xyz="0 1 0" />
    </joint>
    <transmission name="rear_left_wheel_trans" type="SimpleTransmission">
        <type>transmission_interface/SimpleTransmission</type>
        <actuator name="rear_left_wheel_motor">
          <mechanicalReduction>1</mechanicalReduction>
        </actuator>
        <joint name="rear_left_wheel">
          <hardwareInterface>VelocityJointInterface</hardwareInterface>
        </joint>
    </transmission>




    <link name="rear_right_hip">
        <visual>
            <origin rpy="3.14159265359 0 0" xyz="0 0 0"/>
            <geometry>
                <mesh filename="package://legged/models/wheeledspot/meshes/rear_right_hip.dae" />
            </geometry>
        </visual>
        <collision>
            <origin xyz="0.02 -0.015 0" rpy="0 1.5707963268 0"/>
            <geometry>
                <cylinder length="0.15" radius="0.05"/> 
            </geometry>
        </collision>
        <inertial>
            <mass value="1.5" />
            <inertia  ixx="0.0605" ixy="0.0"  ixz="0.0"  iyy="0.0"  iyz="0.0"  izz="0.0" />
        </inertial>
    </link>

    <joint name="rear_right_hip_x" type="fixed">
        <origin xyz="-0.29785 -0.05500 0.00000" rpy="0 0 0" />
        <axis xyz="1 0 0" />
        <parent link="body" />
        <child link="rear_right_hip" />
    </joint>

    <link name="rear_right_upper_leg">
        <visual>
            <origin rpy="3.14159265359 -1.39 0" xyz="0 0 0"/>
            <geometry>
                <mesh filename="package://legged/models/wheeledspot/meshes/rear_right_upper_leg.dae" />
            </geometry>
        </visual>
        <collision>
            <origin xyz="0.0 -0.01 -0.14" rpy="0 0 0"/>
            <geometry>
                <box size="0.1 0.1 0.41"/>
            </geometry>
        </collision>
        <inertial>
            <mass value="1.5" />
            <inertia  ixx="0.0" ixy="0.0"  ixz="0.0"  iyy="0.05"  iyz="0.0"  izz="0.0" />
        </inertial>
    </link>

    <joint name="rear_right_hip_y" type="fixed">
        <origin xyz="0.0 -0.110945 0.0" rpy="0 0 0" />
        <axis xyz="0 1 0" />
        <parent link="rear_right_hip" />
        <child link="rear_right_upper_leg" />
    </joint>

    <!-- <link name="rear_right_lower_leg">
        <visual>
            <origin rpy="3.14159265359 1.48 0" xyz="0 0 0"/>
            <geometry>
                <mesh filename="package://legged/models/wheeledspot/meshes/rear_right_lower_leg.dae" />
            </geometry>
        </visual>
        <collision name='rear_right_lower_leg_fixed_joint_lump__rear_bump_sensor'>
            <origin xyz="0.0 0.00 -0.16" rpy="0 0 0"/>
            <geometry>
                <box size="0.06 0.045 0.42"/>
            </geometry>
        </collision>
        <inertial>
            <mass value="1.0" />
            <inertia  ixx="0.0" ixy="0.0"  ixz="0.0"  iyy="0.045"  iyz="0.0"  izz="0.0" />
        </inertial>
    </link>

    <joint name="rear_right_knee" type="fixed">
        <origin xyz="0.025 0.000 -0.3205" rpy="0 0 0" />
        <axis xyz="0 1 0" />
        <parent link="rear_right_upper_leg" />
        <child link="rear_right_lower_leg" />
    </joint> -->

    <link name="rear_right_wheel_link">
        <contact>
          <lateral_friction value="1.0"/>
          <rolling_friction value="0.0"/>
          <stiffness value="30000"/>
          <damping value="1000"/>
        </contact>
        <inertial>
          <mass value="2.637"/>
          <origin xyz="0 0 0"/>
          <inertia ixx="0.02467" ixy="0" ixz="0" iyy="0.02467" iyz="0" izz="0.04411"/>
        </inertial>
        <visual>
          <origin rpy="0 0 0" xyz="0 0 0"/>
          <geometry>
            <mesh filename="package://legged/models/wheeledspot/meshes/wheel.dae"/>
          </geometry>
          <material name="DarkGrey"/>
        </visual>
        <collision>
          <origin rpy="1.570795 0 0" xyz="0 0 0"/>
          <geometry>
            <cylinder length="0.1143" radius="0.17775"/>
          </geometry>
        </collision>
    </link>
    <!-- <gazebo reference="rear_right_wheel_link">
        <mu1 value="1.0"/>
        <mu2 value="1.0"/>
        <kp value="10000000.0"/>
        <kd value="1.0"/>
        <fdir1 value="1 0 0"/>
        <material>Gazebo/Grey</material>
        <turnGravityOff>false</turnGravityOff>
    </gazebo> -->
    <joint name="rear_right_wheel" type="continuous">
        <origin xyz="0.025 0.000 -0.4205" rpy="0 0 0" />
        <axis xyz="0 1 0" />
        <parent link="rear_right_upper_leg" />
        <child link="rear_right_wheel_link" />
    </joint>
    <transmission name="rear_right_wheel_trans" type="SimpleTransmission">
        <type>transmission_interface/SimpleTransmission</type>
        <actuator name="rear_right_wheel_motor">
          <mechanicalReduction>1</mechanicalReduction>
        </actuator>
        <joint name="rear_right_wheel">
          <hardwareInterface>VelocityJointInterface</hardwareInterface>
        </joint>
    </transmission>

</robot>

